--------------------------------------------------------------------------------
Makelog started: 2023-09-14 16:23:31
Working directory: /Users/conniexu/Documents/Harvard/research projects/Nursing-Homes/connie/clean_hcris/code
--------------------------------------------------------------------------------
*********************************************************************************
* An error was encountered with `link_externals`. Traceback can be found below. *
*********************************************************************************

Traceback (most recent call last):
  File "/Library/Frameworks/Python.framework/Versions/3.10/lib/python3.10/site-packages/gslab_make/move_sources.py", line 351, in link_externals
    source_map = _create_links(paths, file_list)
  File "/Library/Frameworks/Python.framework/Versions/3.10/lib/python3.10/site-packages/gslab_make/move_sources.py", line 53, in _create_links
    move_list = MoveList(file_list, move_dir, paths)
  File "/Library/Frameworks/Python.framework/Versions/3.10/lib/python3.10/site-packages/gslab_make/private/movedirective.py", line 328, in __init__
    self.get_move_directive_list()
  File "/Library/Frameworks/Python.framework/Versions/3.10/lib/python3.10/site-packages/gslab_make/private/movedirective.py", line 379, in get_move_directive_list
    self.move_directive_list = [MoveDirective(file, raw_line, line, self.move_dir) for (file, raw_line, line) in lines]
  File "/Library/Frameworks/Python.framework/Versions/3.10/lib/python3.10/site-packages/gslab_make/private/movedirective.py", line 379, in <listcomp>
    self.move_directive_list = [MoveDirective(file, raw_line, line, self.move_dir) for (file, raw_line, line) in lines]
  File "/Library/Frameworks/Python.framework/Versions/3.10/lib/python3.10/site-packages/gslab_make/private/movedirective.py", line 68, in __init__
    self.check_paths()
  File "/Library/Frameworks/Python.framework/Versions/3.10/lib/python3.10/site-packages/gslab_make/private/movedirective.py", line 119, in check_paths
    raise CritError(messages.crit_error_no_path % self.source)
gslab_make.private.exceptionclasses.CritError: 
ERROR! Path `/Users/conniexu/Dropbox (Harvard University)/NH Ownership/Data/Medicare Cost Reports/Data by Year` cannot be found.

